Workbook

Sheet Key
B2: Key
B4: Main tables | C4: Un-colored tabs, T1-T11
B5: Appendix tables | C5: Peach tabs, AT1-AT7
B6: Disclosed results from Census Bureau, numbered by disclosure number and tab | C6: Grey tabs (16; only results used in tables are included here)
B7: Output of postdisclosure programs | C7: Blue tabs (5, named to correspond to output files)

Sheet T1
B1: Table 1: Characteristics of Samples Derived from Longitudinal Employer-Household Dynamics (LEHD) Data Base
C3: Estimation Sample | D3: Subgroups of Estimation Sample: | G3: Event study samples:
D4: CZ stayers | E4: CZ movers | G4: Firm movers | H4: CZ movers
C5: -1 | D5: -2 | E5: -3 | G5: -4 | H5: -5
B6: ln(quarterly earnings) | C6: =VALUE(disc7.1!B7) -> 9.434 | D6: =VALUE(disc7.1!C7) -> 9.431 | E6: =VALUE(disc7.1!D7) -> 9.441 | G6: =VALUE(disc7.1!E7) -> 9.506 | H6: =VALUE(disc7.1!F7) -> 9.548
B7: (standard deviation) | C7: =VALUE(disc7.1!B8) -> -0.5956 | D7: =VALUE(disc7.1!C8) -> -0.5945 | E7: =VALUE(disc7.1!D8) -> -0.5985 | G7: =VALUE(disc7.1!E8) -> -0.6334 | H7: =VALUE(disc7.1!F8) -> -0.6501
B8: Mean Age | C8: =VALUE(disc7.1!B9) -> 42.44 | D8: =VALUE(disc7.1!C9) -> 43.56 | E8: =VALUE(disc7.1!D9) -> 39.45 | G8: =VALUE(disc7.1!E9) -> 40.93 | H8: =VALUE(disc7.1!F9) -> 40.08
C9: =VALUE(disc7.1!B10) -> -10.78 | D9: =VALUE(disc7.1!C10) -> -10.73 | E9: =VALUE(disc7.1!D10) -> -10.32 | G9: =VALUE(disc7.1!E10) -> -10.63 | H9: =VALUE(disc7.1!F10) -> -10.56
B10: Fraction Female | C10: =VALUE(disc7.1!B11) -> 0.4728 | D10: =VALUE(disc7.1!C11) -> 0.49 | E10: =VALUE(disc7.1!D11) -> 0.4269 | G10: =VALUE(disc7.1!E11) -> 0.4605 | H10: =VALUE(disc7.1!F11) -> 0.4253
B11: Fraction Foreign Born | C11: =VALUE(disc7.1!B13) -> 0.1612 | D11: =VALUE(disc7.1!C13) -> 0.1676 | E11: =VALUE(disc7.1!D13) -> 0.1439 | G11: =VALUE(disc7.1!E13) -> 0.1512 | H11: =VALUE(disc7.1!F13) -> 0.1346
B12: Fraction Hispanic | C12: =VALUE(disc7.1!B15) -> 0.1333 | D12: =VALUE(disc7.1!C15) -> 0.138 | E12: =VALUE(disc7.1!D15) -> 0.1206 | G12: =VALUE(disc7.1!E15) -> 0.1214 | H12: =VALUE(disc7.1!F15) -> 0.1029
B13: Number of CZ's during sample period:
B14: 1 CZ | C14: =VALUE(disc7.1!B17) -> 0.7276 | D14: 1 | E14: =IF(disc7.1!D17="",0,VALUE(disc7.1!D17)) -> 0 | G14: =VALUE(disc7.1!E17) -> 0.6677 | H14: =IF(disc7.1!F17="",0,VALUE(disc7.1!F17)) -> 0
B15: 2 CZ's | C15: =VALUE(disc7.1!B19) -> 0.2033 | D15: =IF(disc7.1!C19="",0,VALUE(disc7.1!C19)) -> 0 | E15: =VALUE(disc7.1!D19) -> 0.7462 | G15: =VALUE(disc7.1!E19) -> 0.3323 | H15: 1
B16: 3+ CZ's | C16: =VALUE(disc7.1!B21) -> 0.06913 | D16: =IF(disc7.1!C21="",0,VALUE(disc7.1!C21)) -> 0 | E16: =VALUE(disc7.1!D21) -> 0.2538 | G16: =IF(disc7.1!E21="",0,VALUE(disc7.1!E21)) -> 0 | H16: =IF(disc7.1!F21="",0,VALUE(disc7.1!F21)) -> 0
B17: Number of 4-digit industries during sample period:
B18: 1 Industry | C18: =VALUE(disc7.1!B23) -> 0.6483 | D18: =VALUE(disc7.1!C23) -> 0.6777 | E18: =VALUE(disc7.1!D23) -> 0.5697 | G18: =VALUE(disc7.1!E23) -> 0.6238 | H18: =VALUE(disc7.1!F23) -> 0.9949
B19: 2 Industries | C19: =VALUE(disc7.1!B25) -> 0.2466 | D19: =VALUE(disc7.1!C25) -> 0.2281 | E19: =VALUE(disc7.1!D25) -> 0.296 | G19: =VALUE(disc7.1!E25) -> 0.3666 | H19: =VALUE(disc7.1!F25) -> 0.005103
B20: 3+ Industries | C20: =VALUE(disc7.1!B27) -> 0.1051 | D20: =VALUE(disc7.1!C27) -> 0.09412 | E20: =VALUE(disc7.1!D27) -> 0.1343 | G20: =VALUE(disc7.1!E27) -> 0.009586 | H20: =IF(disc7.1!F27="",0,VALUE(disc7.1!F27)) -> 0
B22: Number of Quarters Observed | C22: =VALUE(disc7.1!B29) -> 25.88 | D22: =VALUE(disc7.1!C29) -> 26.84 | E22: =VALUE(disc7.1!D29) -> 23.32
B24: Number P-Q obs (millions) | C24: =VALUE(disc7.1!B31)/1000000 -> 2523 | D24: =VALUE(disc7.1!C31)/1000000 -> 1835 | E24: =VALUE(disc7.1!D31)/1000000 -> 687.2 | G24: =VALUE(disc7.1!E31)/1000000 -> 193.4 | H24: =VALUE(disc7.1!F31)/1000000 -> 67.17
B25: Number Persons (millions) | C25: =VALUE(disc7.1!B32)/1000000 -> 112.1 | D25: =VALUE(disc7.1!C32)/1000000 -> 78.59 | E25: =VALUE(disc7.1!D32)/1000000 -> 33.52 | G25: =VALUE(disc7.1!E32)/1000000 -> 19.34 | H25: =VALUE(disc7.1!F32)/1000000 -> 6.717
B27: Notes: Sample includes person-quarter (PQ) observations for indivduals age 22-62 with at least 8 quarters of employment in the LEHD 2010Q1 to 2018Q2. Quarterly observations for individuals with multiple employers are excluded, as are the first and last (transitional) quarters of any spell with the same employer, quarters for which industry or location information is missing, and quarters with earnings less than $3,800. Event study samples use 5 quarters of earnings before a move and 5 quarters after, and are limited to people with a single move (between firms in column 4, or between CZs with no change in industry in column 5) in that window.

Sheet T2
B6: Table 2: Summary of Estimated AKM Model
D9: Person-quarter level | G9: CZ level
D10: Std. Dev. or Correlation | E10: Variance Share | G10: Std. Dev. or Correlation | H10: Variance Share
D11: (1) | E11: (2) | G11: (3) | H11: (4)
B12: Log earnings or mean log earnings | D12: =VALUE(disc7.2!B7) -> 0.6526 | E12: 1 | G12: =VALUE(disc7.2!C7) -> 0.1467 | H12: 1
B13: Variance components (std. deviations in odd-number columns, variance shares in even-numbered columns)
B14: Person effects | D14: =SQRT((D$12^2)*E14) -> 0.52387158 | E14: =VALUE(disc7.2!B8) -> 0.6444 | G14: =SQRT((G$12^2)*H14) -> 0.08079162 | H14: =VALUE(disc7.2!C8) -> 0.3033
B15: Firm effects | D15: =SQRT((D$12^2)*E15) -> 0.22284164 | E15: =VALUE(disc7.2!B9) -> 0.1166 | G15: =SQRT((G$12^2)*H15) -> 0.079353717 | H15: =VALUE(disc7.2!C9) -> 0.2926
B16: Covariate index (Xβ) | D16: =SQRT((D$12^2)*E16) -> 0.13467931 | E16: =VALUE(disc7.2!B10) -> 0.04259 | G16: =SQRT((G$12^2)*H16) -> 0.0057344503 | H16: =VALUE(disc7.2!C10) -> 0.001528
B17: Residual | D17: =SQRT((D$12^2)*E17) -> 0.23210919 | E17: =VALUE(disc7.2!B11) -> 0.1265 | G17: =SQRT((G$12^2)*H17) -> 0 | H17: =IF(disc7.2!C11="",0,VALUE(disc7.2!C11)) -> 0
B18: Covariance components (correlations in odd-number columns, variance shares in even-numbered columns)
B19: Person & firm | D19: =(E19*(D12^2)/2)/(D14*D15) -> 0.18240761 | E19: =VALUE(disc7.2!B12) -> 0.1 | G19: =(H19*(G12^2)/2)/(G14*G15) -> 0.64182189 | H19: =VALUE(disc7.2!C12) -> 0.3824
B20: Person & covariate index | D20: =(E20*(D12^2)/2)/(D14*D16) -> -0.099900213 | E20: =VALUE(disc7.2!B13) -> -0.0331 | G20: =(H20*(G12^2)/2)/(G14*G16) -> 0.22759037 | H20: =VALUE(disc7.2!C13) -> 0.009799
B21: Firm & covariate index | D21: =(E21*(D12^2)/2)/(D15*D16) -> 0.020469759 | E21: =VALUE(disc7.2!B15) -> 0.002885 | G21: =(H21*(G12^2)/2)/(G15*G16) -> 0.24521663 | H21: =VALUE(disc7.2!C15) -> 0.01037
B23: Notes: Table shows variance decompositions based on equation (4). Columns 1-2 pertain to the variance of individual quarterly earnings. Columns 3-4 pertain to the variance of mean earnings by CZ. Entries in columns 1 & 3 for "variance components" are standard deviations of the earnings components indicated in row headings; for "covariance components" they are the estimated correlations of the indicated components. Entries in columns 2 & 4 are variance shares explained by the variance or covariance components.

Sheet T3
B3: Table 3. CZ characteristics and AKM estimates
D5: Explanatory variable (CZ level)
D6: Mean log earnings | E6: Log size | F6: Fraction college
D7: (1) | E7: (2) | F7: (3)
B8: Mean log earnings | D8: 1 | E8: =VALUE(disc7.6!B10) -> 0.0753 | F8: =VALUE(disc7.6!B13) -> 1.683
E9: =VALUE(disc7.6!B11) -> -0.00808 | F9: =VALUE(disc7.6!B14) -> -0.149
B10: Basic decomposition
C11: Mean person effect (skill composition effect) | D11: =VALUE(disc7.6!C6) -> 0.499 | E11: =VALUE(disc7.6!C10) -> 0.0397 | F11: =VALUE(disc7.6!C13) -> 0.982
D12: =VALUE(disc7.6!C7) -> -0.0205 | E12: =VALUE(disc7.6!C11) -> -0.00655 | F12: =VALUE(disc7.6!C14) -> -0.0689
C13: Mean establishment effect (CZ place effect) | D13: =VALUE(disc7.6!D6) -> 0.489 | E13: =VALUE(disc7.6!D10) -> 0.034 | F13: =VALUE(disc7.6!D13) -> 0.664
D14: =VALUE(disc7.6!D7) -> -0.0187 | E14: =VALUE(disc7.6!D11) -> -0.0031 | F14: =VALUE(disc7.6!D14) -> -0.0988
C15: Share of gradient due to skill composition | D15: =D13/D8 -> 0.489 | E15: =E13/E8 -> 0.45152722 | F15: =F13/F8 -> 0.39453357
B16: Measures of dispersion in skill composition
C17: SD of person effects | D17: =VALUE(disc7.6!E6) -> 0.24 | E17: =VALUE(disc7.6!E10) -> 0.025 | F17: =VALUE(disc7.6!E13) -> 0.466
D18: =VALUE(disc7.6!E7) -> -0.0219 | E18: =VALUE(disc7.6!E11) -> -0.00202 | F18: =VALUE(disc7.6!E14) -> -0.0467
C19: Share of workers in bottom decile | D19: =VALUE(disc7.6!F6) -> -0.0871 | E19: =VALUE(disc7.6!F10) -> -0.0048 | F19: =VALUE(disc7.6!F13) -> -0.202
D20: =VALUE(disc7.6!F7) -> -0.0124 | E20: =VALUE(disc7.6!F11) -> -0.00253 | F20: =VALUE(disc7.6!F14) -> -0.0206
C21: Share of workers in top decile | D21: =VALUE(disc7.6!G6) -> 0.213 | E21: =VALUE(disc7.6!G10) -> 0.0185 | F21: =VALUE(disc7.6!G13) -> 0.414
D22: =VALUE(disc7.6!G7) -> -0.00948 | E22: =VALUE(disc7.6!G11) -> -0.00221 | F22: =VALUE(disc7.6!G14) -> -0.0335
B23: Decomposition of CZ earnings effect
C24: CZ premium (B) | D24: =VALUE(disc7.6!H6) -> 0.475 | E24: =VALUE(disc7.6!H10) -> 0.037 | F24: =VALUE(disc7.6!H13) -> 0.733
D25: =VALUE(disc7.6!H7) -> -0.0188 | E25: =VALUE(disc7.6!H11) -> -0.00262 | F25: =VALUE(disc7.6!H14) -> -0.0894
C26: Industry composition | D26: =VALUE(disc7.6!I6) -> 0.0181 | E26: =VALUE(disc7.6!I10) -> 3.69e-05 | F26: =VALUE(disc7.6!I13) -> -0.00953
D27: =VALUE(disc7.6!I7) -> -0.00641 | E27: =VALUE(disc7.6!I11) -> -0.000402 | F27: =VALUE(disc7.6!I14) -> -0.0125
C28: Interaction | D28: =VALUE(disc7.6!J6) -> -0.00445 | E28: =VALUE(disc7.6!J10) -> -0.00313 | F28: =VALUE(disc7.6!J13) -> -0.0594
D29: =VALUE(disc7.6!J7) -> -0.0084 | E29: =VALUE(disc7.6!J11) -> -0.000832 | F29: =VALUE(disc7.6!J14) -> -0.0145
B30: Within-CZ skill-match
C31: Correlation of person & firm effect within CZ | D31: =VALUE(disc7.6!K6) -> 0.451 | E31: =VALUE(disc7.6!K10) -> 0.0394 | F31: =VALUE(disc7.6!K13) -> 0.85
D32: =VALUE(disc7.6!K7) -> -0.0251 | E32: =VALUE(disc7.6!K11) -> -0.00354 | F32: =VALUE(disc7.6!K14) -> -0.0567
B34: Notes: Table shows regressions of mean log earnings and other CZ-level measures on CZ mean log earnings, log size, or the fraction of workers with some college or more. Regressions are weighted by CZ size, measured as the number of person-quarter observations in our sample in the CZ.

Sheet T4
B2: Table 4: Mean Log Earnings and Components of Earnings for Groups of CZ's
D4: Ranked By CZ Effect (Ψc) | I4: Grouped By Quintile of CZ Effect (Ψc; 1=lowest)
D5: Top 10 | F5: Middle Range | G5: Bottom 10
C6: All | D6: Large Urban | E6: Resource Intensive | I6: 1 | J6: 2 | K6: 3 | L6: 4 | M6: 5
C7: (1) | D7: (2) | E7: (3) | F7: (4) | G7: (5) | I7: (6) | J7: (7) | K7: (8) | L7: (9) | M7: (10)
B8: Log Earnings | C8: =VALUE(disc7.20!B7) -> 9.263 | D8: =VALUE(disc7.20!D7) -> 9.723 | E8: =VALUE(disc7.20!E7) -> 9.539 | F8: =VALUE(disc7.20!F7) -> 9.285 | G8: =VALUE(disc7.20!G7) -> 9.127 | I8: =VALUE(disc7.20!H7) -> 9.143 | J8: =VALUE(disc7.20!I7) -> 9.198 | K8: =VALUE(disc7.20!J7) -> 9.252 | L8: =VALUE(disc7.20!K7) -> 9.305 | M8: =VALUE(disc7.20!L7) -> 9.419
C9: =VALUE(disc7.20!B8) -> -0.124 | D9: =VALUE(disc7.20!D8) -> -0.0823 | E9: =VALUE(disc7.20!E8) -> -0.0508 | F9: =VALUE(disc7.20!F8) -> -0.102 | G9: =VALUE(disc7.20!G8) -> -0.0694 | I9: =VALUE(disc7.20!H8) -> -0.0621 | J9: =VALUE(disc7.20!I8) -> -0.0535 | K9: =VALUE(disc7.20!J8) -> -0.0638 | L9: =VALUE(disc7.20!K8) -> -0.0715 | M9: =VALUE(disc7.20!L8) -> -0.127
B11: Person Effect | C11: =VALUE(disc7.20!B10) -> 9.019 | D11: =VALUE(disc7.20!D10) -> 9.244 | E11: =VALUE(disc7.20!E10) -> 9.068 | F11: =VALUE(disc7.20!F10) -> 9.037 | G11: =VALUE(disc7.20!G10) -> 8.997 | I11: =VALUE(disc7.20!H10) -> 8.994 | J11: =VALUE(disc7.20!I10) -> 8.998 | K11: =VALUE(disc7.20!J10) -> 9.017 | L11: =VALUE(disc7.20!K10) -> 9.037 | M11: =VALUE(disc7.20!L10) -> 9.049
C12: =VALUE(disc7.20!B11) -> -0.0683 | D12: =VALUE(disc7.20!D11) -> -0.0284 | E12: =VALUE(disc7.20!E11) -> -0.0323 | F12: =VALUE(disc7.20!F11) -> -0.0664 | G12: =VALUE(disc7.20!G11) -> -0.0556 | I12: =VALUE(disc7.20!H11) -> -0.0527 | J12: =VALUE(disc7.20!I11) -> -0.0498 | K12: =VALUE(disc7.20!J11) -> -0.059 | L12: =VALUE(disc7.20!K11) -> -0.0665 | M12: =VALUE(disc7.20!L11) -> -0.0891
B14: CZ effect | C14: =VALUE(disc7.20!B13) -> 0.183 | D14: =VALUE(disc7.20!D13) -> 0.407 | E14: =VALUE(disc7.20!E13) -> 0.414 | F14: =VALUE(disc7.20!F13) -> 0.183 | G14: =VALUE(disc7.20!G13) -> 0.0673 | I14: =VALUE(disc7.20!H13) -> 0.0877 | J14: =VALUE(disc7.20!I13) -> 0.139 | K14: =VALUE(disc7.20!J13) -> 0.172 | L14: =VALUE(disc7.20!K13) -> 0.206 | M14: =VALUE(disc7.20!L13) -> 0.31
C15: =VALUE(disc7.20!B14) -> -0.0866 | D15: =VALUE(disc7.20!D14) -> -0.0566 | E15: =VALUE(disc7.20!E14) -> -0.0288 | F15: =VALUE(disc7.20!F14) -> -0.0532 | G15: =VALUE(disc7.20!G14) -> -0.0177 | I15: =VALUE(disc7.20!H14) -> -0.0278 | J15: =VALUE(disc7.20!I14) -> -0.0105 | K15: =VALUE(disc7.20!J14) -> -0.00951 | L15: =VALUE(disc7.20!K14) -> -0.0115 | M15: =VALUE(disc7.20!L14) -> -0.0927
B17: Covariates | C17: =VALUE(disc7.20!B16) -> 0.0613 | D17: =VALUE(disc7.20!D16) -> 0.073 | E17: =VALUE(disc7.20!E16) -> 0.0569 | F17: =VALUE(disc7.20!F16) -> 0.0648 | G17: =VALUE(disc7.20!G16) -> 0.0629 | I17: =VALUE(disc7.20!H16) -> 0.061 | J17: =VALUE(disc7.20!I16) -> 0.0615 | K17: =VALUE(disc7.20!J16) -> 0.0627 | L17: =VALUE(disc7.20!K16) -> 0.0619 | M17: =VALUE(disc7.20!L16) -> 0.0595
C18: =VALUE(disc7.20!B17) -> -0.0107 | D18: =VALUE(disc7.20!D17) -> -0.0046 | E18: =VALUE(disc7.20!E17) -> -0.0199 | F18: =VALUE(disc7.20!F17) -> -0.00546 | G18: =VALUE(disc7.20!G17) -> -0.00747 | I18: =VALUE(disc7.20!H17) -> -0.00854 | J18: =VALUE(disc7.20!I17) -> -0.00939 | K18: =VALUE(disc7.20!J17) -> -0.00764 | L18: =VALUE(disc7.20!K17) -> -0.00776 | M18: =VALUE(disc7.20!L17) -> -0.017
B20: Notes: Analyses are weighted by CZ size. Mean and standard deviations (in parentheses) are based on the across-CZ distribution. Columns 2-5 include only CZs with at least 25,000 people.

Sheet T5
B6: Table 5: Dynamic specifications, estimated on younger workers
D8: AKM models estimated on young subsample
D9: No dynamics | F9: Dynamic models, large CZs defined as:
F10: 10 Largest CZ's | G10: 25 Largest CZ's
D11: (1) | F11: (2) | G11: (3)
B13: A. Regression of CZ effect from alternative specification on CZ effect from baseline specification
B14: Std. dev. of estimated CZ effects | D14: =VALUE(disc7.7!D15) -> 0.0782 | F14: =VALUE(disc7.7!E15) -> 0.0767 | G14: =VALUE(disc7.7!F15) -> 0.0776
B15: Slope coefficient from regression on | D15: =VALUE(disc7.7!D9) -> 0.956 | F15: =VALUE(disc7.7!E9) -> 0.937 | G15: =VALUE(disc7.7!F9) -> 0.95
B16: CZ effects from main model | D16: =VALUE(disc7.7!D10) -> -0.0313 | F16: =VALUE(disc7.7!E10) -> -0.031 | G16: =VALUE(disc7.7!F10) -> -0.0308
B17: R-squared coefficient | D17: =VALUE(disc7.7!D14) -> 0.942 | F17: =VALUE(disc7.7!E14) -> 0.94 | G17: =VALUE(disc7.7!F14) -> 0.942
B19: B. Estimated effects of work experience from dynamic specification:
B20: Years of work experience in any CZ | F20: =disc7.3!B10*4 -> 0.017068 | G20: =disc7.3!C10*4 -> 0.013928
F21: =disc7.3!B11*4 -> -0.0013428 | G21: =disc7.3!C11*4 -> -0.0014756
B23: Years of work experience in large CZ | F23: =disc7.3!B13*4 -> 0.016244 | G23: =disc7.3!C22*4 -> 0.015816
F24: =disc7.3!B14*4 -> -0.006908 | G24: =disc7.3!C23*4 -> -0.0039404
B26: Years of work experience in any CZ | F26: =disc7.3!B16*4 -> 0.00716 | G26: =disc7.3!C25*4 -> 0.0018564
B27: × in large CZ | F27: =disc7.3!B17*4 -> -0.00662 | G27: =disc7.3!C26*4 -> -0.0038196
B29: Years of work experience in large CZ | F29: =disc7.3!B19*4 -> -0.007844 | G29: =disc7.3!C28*4 -> -0.001532
B30: × in large CZ | F30: =disc7.3!B20*4 -> -0.0012028 | G30: =disc7.3!C29*4 -> -0.0010176
B33: Notes: Panel A shows regressions of estimated CZ effects from alternative models, all estimated using only individuals under age 26 in 2010, on the CZ effects from our main specification. Number of observations is 741 (regressions weighted by CZ size). Robust standard errors in parentheses. Panel B shows estimated regression coefficients for experience terms from the dynamic specifications. In column 2, "large CZs" are the 10 largest CZ's, and "large CZ experience" is previous quarters of work in these 10 CZs. In column 3, "large CZs" are the 25 largest CZ's, with "large CZ experience" defined commensurately. Standard errors, clustered by the first CZ in which a person is observed in our sample, in parentheses.

Sheet T6
B2: Table 6. Comparisons of Estimated CZ Pay Premiums from Alternative Specifications to Estimates from Preferred Approach
D4: Preferred model | F4: Models with Person and Aggregated Place Effects | I4: Cross-sectional models fit to ACS
D5: -1 | F5: -2 | G5: -3 | I5: -4 | J5: -5 | K5: -6 | L5: -7
B6: Alternative model controls for:
C7: Year effects and age/experience | D7: X | F7: X | G7: X | J7: X | K7: X | L7: X
C8: Educ., experience, gender, race | J8: X | K8: X | L8: X
C9: Region of origin & field of study | K9: X | L9: X
C10: Detailed industry | L10: X
C11: Person fixed effects | D11: X | F11: X | G11: X
C12: Firm fixed effects | D12: X
C13: CZ fixed effects | F13: X
C14: Industry-by-CZ fixed effects | G14: X
B16: Standard deviation of CZ effects | D16: ='T2'!G15 -> 0.079353717 | F16: =VALUE(disc7.7!C15) -> 0.0638 | G16: =VALUE(disc7.7!B15) -> 0.0648 | I16: =tab6_external!D4 -> 0.141 | J16: =tab6_external!D5 -> 0.117 | K16: =tab6_external!D6 -> 0.111 | L16: =tab6_external!D7 -> 0.106
B18: Regression of CZ effects from alt. model on preferred estimates | D18: 1 | F18: =VALUE(disc7.7!C9) -> 0.771 | G18: =VALUE(disc7.7!B9) -> 0.794 | I18: =VALUE(disc9.1!B6) -> 1.432 | J18: =VALUE(disc9.1!C6) -> 1.331 | K18: =VALUE(disc9.1!D6) -> 1.265 | L18: =VALUE(disc9.1!E6) -> 1.181
F19: =VALUE(disc7.7!C10) -> -0.0213 | G19: =VALUE(disc7.7!B10) -> -0.0203 | I19: =VALUE(disc9.1!B7) -> -0.107 | J19: =VALUE(disc9.1!C7) -> -0.0534 | K19: =VALUE(disc9.1!D7) -> -0.058 | L19: =VALUE(disc9.1!E7) -> -0.0616
B20: R2 (adjusted) | D20: 1 | F20: =VALUE(disc7.7!C14) -> 0.919 | G20: =VALUE(disc7.7!B14) -> 0.945 | I20: =VALUE(disc9.1!B9) -> 0.656 | J20: =VALUE(disc9.1!C9) -> 0.816 | K20: =VALUE(disc9.1!D9) -> 0.813 | L20: =VALUE(disc9.1!E9) -> 0.777
B22: Note: Preferred model construct CZ effects as averages of firm effects from AKM specification, as in equation (3). Regressions are of CZ effects from alternative models on CZ effects from preferred model, and are weighted by the number of person-quarter observations in the CZ (in columns 2-3) or by the weighted number of ACS wage observations in the CZ (in columns 4-7). Alternative models in columns 2-3 are fit to LEHD with person effects and CZ or CZ-by-industry effects, and include the same year and age effects as the preferred model. Alternative models in columns 4-7 are fit to the ACS with observed control variables and CZ effects. Robust standard errors in parentheses.

Sheet T7
B6: Table 7: Simple Linear Regression Models for Estimated CZ-Industry Effects
D9: CZ Effects only | E9: Industry Effects only | F9: Models with CZ and Industry Effects:
F10: No other controls | G10: Plus local emp. share of industry | H10: Plus log of local emp. share of industry
D11: (1) | E11: (2) | F11: (3) | G11: (4) | H11: (5)
B12: Share of CZ emp. in industry | D12: -- | E12: -- | F12: -- | G12: =VALUE(SUBSTITUTE(disc7.4!E6,"*", "")) -> 0.451 | H12: --
G13: =VALUE(disc7.4!E7) -> -0.0325
B14: Log share of CZ emp. in industry | D14: -- | E14: -- | F14: -- | G14: -- | H14: =VALUE(SUBSTITUTE(disc7.4!F9,"*", "")) -> 0.044 | K14: =SUBSTITUTE(disc7.4!J9,"*", "")
H15: =VALUE(disc7.4!F10) -> -0.00244
B16: R-squared | D16: =VALUE(disc7.4!B14) -> 0.326 | E16: =VALUE(disc7.4!C14) -> 0.57 | F16: =VALUE(disc7.4!D14) -> 0.873 | G16: =VALUE(disc7.4!E14) -> 0.885 | H16: =VALUE(disc7.4!F14) -> 0.892
B17: Root Mean Squared Error | D17: =VALUE(disc7.4!B15) -> 0.117 | E17: =VALUE(disc7.4!C15) -> 0.0912 | F17: =VALUE(disc7.4!D15) -> 0.0506 | G17: =VALUE(disc7.4!E15) -> 0.0483 | H17: =VALUE(disc7.4!F15) -> 0.0467
B19: Notes: Table shows goodness of fit and estimated regression coefficients from regression of estimated CZ-by-2-digit-industry effects on CZ indicators (column 1), industry indicators (column 2), and CZ and industry indicators (columns 3-5). Models in columns 4-5 include the share (or log share) of CZ employment in the industry. Models are fit to person-quarter data after assigning estimated CZ-industry effect and all control variables to each person-quarter observation.

Sheet T8
B6: Table 8: Decomposition of Variance of Average CZ Earnings Premium
C8: 2-digit industries | D8: 4-digit industries
C9: (2) | D9: (3)
B10: Standard Dev. of Average CZ premium | C10: =VALUE(disc7.5!B5) -> 0.07934 | D10: =VALUE(disc7.5!C5) -> 0.07934
B11: Decomposition (variance shares):
B12: Var(Average Earnings Premium) | C12: =VALUE(disc7.5!B7) -> 0.9424 | D12: =VALUE(disc7.5!C7) -> 0.913
B13: Var(Composition Effect) | C13: =VALUE(disc7.5!B8) -> 0.02522 | D13: =VALUE(disc7.5!C8) -> 0.02578
B14: Var(Interaction Effect) | C14: =VALUE(disc7.5!B9) -> 0.02197 | D14: =VALUE(disc7.5!C9) -> 0.04399
B15: Cov(Earnings Premium, Composition Effect) | C15: =VALUE(disc7.5!B13) -> 0.01521 | D15: =VALUE(disc7.5!C13) -> 0.06354
B16: Cov(Earnings Premium, Interaction Effect) | C16: =VALUE(disc7.5!B14) -> -0.005893 | D16: =VALUE(disc7.5!C14) -> -0.05435
B17: Cov(Composition Effect, Interaction) | C17: =VALUE(disc7.5!B15) -> 0.001096 | D17: =VALUE(disc7.5!C15) -> 0.008037
B19: Notes: Table shows decomposition of the variance of estimated average CZ wage premium, based on equation (9) in text. Decompositions uses 24 2-digit industries (column 1) or 312 4-digit industries (column 2) to define CZ-by-industry effects.

Sheet T9
B3: Table 9. Decomposition of Effect of CZ Characteristics on CZ Earnings Effects
D5: CZ Characteristic (explanatory variable)
D6: Mean log earnings | E6: Log size | F6: College share
D7: (1) | E7: (2) | F7: (3)
B8: Mean log earnings | D8: 1 | E8: =VALUE(disc7.6!B10) -> 0.0753 | F8: =VALUE(disc7.6!B13) -> 1.683
E9: =VALUE(disc7.6!B11) -> -0.00808 | F9: =VALUE(disc7.6!B14) -> -0.149
B10: Basic decomposition
C11: Mean person effect | D11: =VALUE(disc7.6!C6) -> 0.499 | E11: =VALUE(disc7.6!C10) -> 0.0397 | F11: =VALUE(disc7.6!C13) -> 0.982
D12: =VALUE(disc7.6!C7) -> -0.0205 | E12: =VALUE(disc7.6!C11) -> -0.00655 | F12: =VALUE(disc7.6!C14) -> -0.0689
C13: CZ earnings effect | D13: =VALUE(disc7.6!D6) -> 0.489 | E13: =VALUE(disc7.6!D10) -> 0.034 | F13: =VALUE(disc7.6!D13) -> 0.664
D14: =VALUE(disc7.6!D7) -> -0.0187 | E14: =VALUE(disc7.6!D11) -> -0.0031 | F14: =VALUE(disc7.6!D14) -> -0.0988
C15: Share of gradient due to skills | D15: =D11/D8 -> 0.499 | E15: =E11/E8 -> 0.52722444 | F15: =F11/F8 -> 0.58348188
B16: Measures of dispersion in skill composition
C17: SD of person effects | D17: =VALUE(disc7.6!E6) -> 0.24 | E17: =VALUE(disc7.6!E10) -> 0.025 | F17: =VALUE(disc7.6!E13) -> 0.466
D18: =VALUE(disc7.6!E7) -> -0.0219 | E18: =VALUE(disc7.6!E11) -> -0.00202 | F18: =VALUE(disc7.6!E14) -> -0.0467
C19: Share of workers in bottom decile | D19: =VALUE(disc7.6!F6) -> -0.0871 | E19: =VALUE(disc7.6!F10) -> -0.0048 | F19: =VALUE(disc7.6!F13) -> -0.202
D20: =VALUE(disc7.6!F7) -> -0.0124 | E20: =VALUE(disc7.6!F11) -> -0.00253 | F20: =VALUE(disc7.6!F14) -> -0.0206
C21: Share of workers in top decile | D21: =VALUE(disc7.6!G6) -> 0.213 | E21: =VALUE(disc7.6!G10) -> 0.0185 | F21: =VALUE(disc7.6!G13) -> 0.414
D22: =VALUE(disc7.6!G7) -> -0.00948 | E22: =VALUE(disc7.6!G11) -> -0.00221 | F22: =VALUE(disc7.6!G14) -> -0.0335
B23: Decomposition of CZ earnings effect (based on equation 9)
C24: Average earnings premium | D24: =VALUE(disc7.6!H6) -> 0.475 | E24: =VALUE(disc7.6!H10) -> 0.037 | F24: =VALUE(disc7.6!H13) -> 0.733
C25: (term 1 in equation 9) | D25: =VALUE(disc7.6!H7) -> -0.0188 | E25: =VALUE(disc7.6!H11) -> -0.00262 | F25: =VALUE(disc7.6!H14) -> -0.0894
C26: Industry composition effect | D26: =VALUE(disc7.6!I6) -> 0.0181 | E26: =VALUE(disc7.6!I10) -> 3.69e-05 | F26: =VALUE(disc7.6!I13) -> -0.00953
C27: (term 2 in equation 9) | D27: =VALUE(disc7.6!I7) -> -0.00641 | E27: =VALUE(disc7.6!I11) -> -0.000402 | F27: =VALUE(disc7.6!I14) -> -0.0125
C28: Interaction effect | D28: =VALUE(disc7.6!J6) -> -0.00445 | E28: =VALUE(disc7.6!J10) -> -0.00313 | F28: =VALUE(disc7.6!J13) -> -0.0594
C29: (term 3 in equation 9) | D29: =VALUE(disc7.6!J7) -> -0.0084 | E29: =VALUE(disc7.6!J11) -> -0.000832 | F29: =VALUE(disc7.6!J14) -> -0.0145
B30: Within-CZ skill-match
C31: Correlation of person & firm effect within CZ | D31: =VALUE(disc7.6!K6) -> 0.451 | E31: =VALUE(disc7.6!K10) -> 0.0394 | F31: =VALUE(disc7.6!K13) -> 0.85
D32: =VALUE(disc7.6!K7) -> -0.0251 | E32: =VALUE(disc7.6!K11) -> -0.00354 | F32: =VALUE(disc7.6!K14) -> -0.0567
C36: (term 3 in equation 9)
B43: Notes: Table shows regressions of mean log earnings and components of the decomposition given by equations (6) and (9) on CZ mean log earnings, log size, or the fraction of workers with some college or more. Regressions are weighted by CZ size.

Sheet T10
B3: Table 10. Decomposition of CZ Size Elasticity of Mean Wage by Education Group
E6: Less educated workers | H6: More educated workers | K6: Difference, more educated - less educated
E7: Coefficient | F7: Share | H7: Coefficient | I7: Share | K7: Coefficient | L7: Share
E8: (1) | F8: (2) | H8: (3) | I8: (4) | K8: (5) | L8: (6)
B9: Log earnings | E9: =VALUE(disc7.16!B7) -> 0.0389 | F9: =E9/E$9 -> 1 | H9: =VALUE(disc7.16!E7) -> 0.102 | I9: =H9/H$9 -> 1 | K9: =H9-E9 -> 0.0631 | L9: =K9/K$9 -> 1
E10: =VALUE(disc7.16!B8) -> -0.00555 | H10: =VALUE(disc7.16!E8) -> -0.00826 | K10: =-1*SQRT(E10^2+H10^2) -> -0.0099513868
B11: Components
C12: Mean person effect | E12: =VALUE(disc7.16!C7) -> 0.0169 | F12: =E12/E$9 -> 0.4344473 | H12: =VALUE(disc7.16!F7) -> 0.0578 | I12: =H12/H$9 -> 0.56666667 | K12: =H12-E12 -> 0.0409 | L12: =K12/K$9 -> 0.6481775
C13: (skill composition effect) | E13: =VALUE(disc7.16!C8) -> -0.00541 | H13: =VALUE(disc7.16!F8) -> -0.00647 | K13: =-1*SQRT(E13^2+H13^2) -> -0.008433801
C14: Mean establishment effect | E14: =VALUE(disc7.16!D7) -> 0.0199 | F14: =E14/E$9 -> 0.51156812 | H14: =VALUE(disc7.16!G7) -> 0.0425 | I14: =H14/H$9 -> 0.41666667 | K14: =H14-E14 -> 0.0226 | L14: =K14/K$9 -> 0.35816165
C15: (CZ place effect) | E15: =VALUE(disc7.16!D8) -> -0.00206 | H15: =VALUE(disc7.16!G8) -> -0.00324 | K15: =-1*SQRT(E15^2+H15^2) -> -0.003839427
B17: Notes: Table shows regressions of mean log earnings by education group (high school or less vs. some college or more) and components of the decomposition given by equation (6) on CZ mean log earnings, log size, or the fraction of workers with some college or more. Regressions are weighted by the number of person-quarter observations in the relevant education group. Column 5 represents the difference between column 3 and column 2; standard errors assume estimates are independent across the education groups.

Sheet T11
A3: Table 11. Decomposition of Variation in the CZ-level Return to Education
D5: Explanatory variable:
D6: Mean log earnings in CZ | G6: Log CZ size
D7: Coefficient | E7: Share | G7: Coefficient | H7: Share
D8: (1) | E8: (2) | G8: (3) | H8: (4)
A9: Overall earnings gap between more and less educated workers | D9: =VALUE(disc7.14!B7) -> 0.628 | E9: 1 | G9: =VALUE(disc7.14!B10) -> 0.0599 | H9: 1
D10: =VALUE(disc7.14!B8) -> -0.0487 | G10: =VALUE(disc7.14!B11) -> -0.00284
A11: Components
B12: Person effects | D12: =VALUE(disc7.14!D7) -> 0.398 | E12: 0.63375796 | G12: =VALUE(disc7.14!D10) -> 0.0409 | H12: 0.68280467
D13: =VALUE(disc7.14!D8) -> -0.0336 | G13: =VALUE(disc7.14!D11) -> -0.00174
B14: Establishment effects (CZ | D14: =VALUE(disc9.5!B9) -> 0.233 | E14: =+D14/D9 -> 0.37101911 | G14: =VALUE(disc9.5!B13) -> 0.0198 | H14: =+G14/G9 -> 0.33055092
B15: wage effect) | D15: =VALUE(disc9.5!B10) -> -0.0171 | G15: =VALUE(disc9.5!B14) -> -0.00123
B16: Covariates | D16: =VALUE(disc7.14!G7) -> -0.00332 | E16: -0.0052866242 | G16: =VALUE(disc7.14!G10) -> -0.000809 | H16: -0.013505843
D17: =VALUE(disc7.14!G8) -> -0.00269 | G17: =VALUE(disc7.14!G11) -> -0.000434
B18: CZ wage effect components
C19: Relative wage premium | D19: =VALUE(disc7.14!C7) -> 0.0741 | E19: 0.11799363 | G19: =VALUE(disc7.14!C10) -> 0.0067 | H19: 0.11185309
D20: =VALUE(disc7.14!C8) -> -0.00941 | G20: =VALUE(disc7.14!C11) -> -0.000441
C21: Composition | D21: =VALUE(disc7.14!E7) -> 0.165 | E21: 0.26273885 | G21: =VALUE(disc7.14!E10) -> 0.0133 | H21: 0.22203673
D22: =VALUE(disc7.14!E8) -> -0.0114 | G22: =VALUE(disc7.14!E11) -> -0.00104
C23: Interaction | D23: =VALUE(disc7.14!F7) -> -0.00637 | E23: -0.010143312 | G23: =VALUE(disc7.14!F10) -> -0.000229 | H23: -0.0038230384
D24: =VALUE(disc7.14!F8) -> -0.00242 | G24: =VALUE(disc7.14!F11) -> -0.000115
C25: Sum of relative wage premium and interaction | D25: =VALUE(disc7.14!H7) -> 0.0677 | E25: 0.10780255 | G25: =VALUE(disc7.14!H10) -> 0.00647 | H25: 0.10801336
D26: =VALUE(disc7.14!H8) -> -0.0074 | G26: =VALUE(disc7.14!H11) -> -0.000427
A28: Notes: Table shows regressions of the difference in mean log earnings of college and non-college workers in a CZ, or components of the decomposition given by equations (12) and (13), on CZ mean log earnings and log size. Regressions are weighted by CZ size.

Sheet AT1
A4: Appendix Table 1: CZ size effects on log hourly wages and log annual earnings, ACS data
C6: Unadjusted | E6: CZ Effect | G6: CZ Effect
E7: from Model 2 | G7: from Model 3
C8: (1) | E8: (2) | G8: (3)
A10: All Workers
B11: Log hourly wage | C11: =apptab1!B5 -> 0.06765 | E11: =apptab1!C5 -> 0.059 | G11: =apptab1!D5 -> 0.05619
C12: =apptab1!B6 -> 0.00999 | E12: =apptab1!C6 -> 0.00484 | G12: =apptab1!D6 -> 0.00446
C13: =apptab1!B11 -> 0.49732 | E13: =apptab1!C11 -> 0.60724 | G13: =apptab1!D11 -> 0.60481
B15: Log annual earnings | C15: =apptab1!E5 -> 0.07837 | E15: =apptab1!F5 -> 0.05936 | G15: =apptab1!G5 -> 0.06007
C16: =apptab1!E6 -> 0.01296 | E16: =apptab1!F6 -> 0.00655 | G16: =apptab1!G6 -> 0.00614
C17: =apptab1!E11 -> 0.48929 | E17: =apptab1!F11 -> 0.54144 | G17: =apptab1!G11 -> 0.59033
A19: High School-educated Workers (12 years education)
B20: Log hourly wage | C20: =apptab1!H5 -> 0.03117 | E20: =apptab1!I5 -> 0.04958 | G20: =apptab1!J5 -> 0.04872
C21: =apptab1!H6 -> 0.00447 | E21: =apptab1!I6 -> 0.00373 | G21: =apptab1!J6 -> 0.00392
C22: =apptab1!H11 -> 0.30757 | E22: =apptab1!I11 -> 0.54774 | G22: =apptab1!J11 -> 0.54707
B24: Log annual earnings | C24: =apptab1!K5 -> 0.02782 | E24: =apptab1!L5 -> 0.04562 | G24: =apptab1!M5 -> 0.05004
C25: =apptab1!K6 -> 0.00546 | E25: =apptab1!L6 -> 0.00488 | G25: =apptab1!M6 -> 0.00541
C26: =apptab1!K11 -> 0.21369 | E26: =apptab1!L11 -> 0.42639 | G26: =apptab1!M11 -> 0.51115
A28: Some College or More Workers(>12 years education)
B29: Log hourly wage | C29: =apptab1!N5 -> 0.08158 | E29: =apptab1!O5 -> 0.06973 | G29: =apptab1!P5 -> 0.06479
C30: =apptab1!N6 -> 0.00935 | E30: =apptab1!O6 -> 0.00541 | G30: =apptab1!P6 -> 0.00465
C31: =apptab1!N11 -> 0.5908 | E31: =apptab1!O11 -> 0.65808 | G31: =apptab1!P11 -> 0.65464
B33: Log annual earnings | C33: =apptab1!Q5 -> 0.09189 | E33: =apptab1!R5 -> 0.07244 | G33: =apptab1!S5 -> 0.06884
C34: =apptab1!Q6 -> 0.01304 | E34: =apptab1!R6 -> 0.00731 | G34: =apptab1!S6 -> 0.00607
C35: =apptab1!Q11 -> 0.5507 | E35: =apptab1!R11 -> 0.60651 | G35: =apptab1!S11 -> 0.63823
A37: Note: Table entries are estimated regression coefficient, robust standard error (in parentheses) and R-squared [in square brackets] from OLS regression of estimated CZ wage or earnings differential on log of CZ size. Models in column 1 are fit to unadjusted mean log hourly wages or mean log annual earnings. Models in columns 2 and 3 are fit to adjusted CZ earnings differentials derived from models described in text. All models are fit by weighted least squares using as a weight the total number of worker observations for the CZ in the 2010-2018 ACS sample.

Sheet AT2
A1: Appendix Table 2: Models for CZ employment rates and average hours, ACS data
B3: Both Genders | F3: Males only | J3: Females only
B4: Regressed on log(size) | C4: Regressed on mean log wage in CZ | F4: Regressed on log(size) | G4: Regressed on mean log wage in CZ | J4: Regressed on log(size) | K4: Regressed on mean log wage in CZ
C5: Unadjusted | D5: Adjusted | G5: Unadjusted | H5: Adjusted | K5: Unadjusted | L5: Adjusted
B7: (1) | C7: (2) | D7: (3) | F7: (4) | G7: (5) | H7: (6) | J7: (7) | K7: (8) | L7: (9)
A8: Dependent Variable = CZ-mean of:
A9: Employed last year | B9: =apptab2!B5 -> 0.00504 | C9: =apptab2!C7 -> 0.14941 | D9: =apptab2!D9 -> 0.12023 | F9: =apptab2!E5 -> 0.00953 | G9: =apptab2!F7 -> 0.16536 | H9: =apptab2!G9 -> 0.16634 | J9: =apptab2!H5 -> 0.0009 | K9: =apptab2!I7 -> 0.1349 | L9: =apptab2!J9 -> 0.07518
B10: =apptab2!B6 -> 0.00294 | C10: =apptab2!C8 -> 0.0217 | D10: =apptab2!D10 -> 0.03335 | F10: =apptab2!E6 -> 0.00257 | G10: =apptab2!F8 -> 0.02173 | H10: =apptab2!G10 -> 0.03176 | J10: =apptab2!H6 -> 0.00358 | K10: =apptab2!I8 -> 0.02356 | L10: =apptab2!J10 -> 0.03886
A12: Employed last year | B12: =apptab2!K5 -> -0.00017 | C12: =apptab2!L7 -> 0.06792 | D12: =apptab2!M9 -> 0.03779 | F12: =apptab2!N5 -> 0.00064 | G12: =apptab2!O7 -> 0.05821 | H12: =apptab2!P9 -> 0.03469 | J12: =apptab2!Q5 -> -0.00097 | K12: =apptab2!R7 -> 0.07753 | L12: =apptab2!S9 -> 0.0416
A13: (adjusted) | B13: =apptab2!K6 -> 0.0021 | C13: =apptab2!L8 -> 0.01718 | D13: =apptab2!M10 -> 0.0262 | F13: =apptab2!N6 -> 0.0022 | G13: =apptab2!O8 -> 0.01969 | H13: =apptab2!P10 -> 0.02853 | J13: =apptab2!Q6 -> 0.00213 | K13: =apptab2!R8 -> 0.01588 | L13: =apptab2!S10 -> 0.02576
A15: Hours last year | B15: =apptab2!T5 -> 11.42025 | C15: =apptab2!U7 -> 336.90834 | D15: =apptab2!V9 -> 283.25414 | F15: =apptab2!W5 -> 15.62253 | G15: =apptab2!X7 -> 358.57266 | H15: =apptab2!Y9 -> 345.52162 | J15: =apptab2!Z5 -> 9.03914 | K15: =apptab2!AA7 -> 325.49718 | L15: =apptab2!AB9 -> 230.21642
B16: =apptab2!T6 -> 8.27389 | C16: =apptab2!U8 -> 49.12579 | D16: =apptab2!V10 -> 83.07881 | F16: =apptab2!W6 -> 8.20693 | G16: =apptab2!X8 -> 53.20307 | H16: =apptab2!Y10 -> 85.86109 | J16: =apptab2!Z6 -> 8.99576 | K16: =apptab2!AA8 -> 49.57694 | L16: =apptab2!AB10 -> 87.05586
A18: Hours last year | B18: =apptab2!AC5 -> -3.8224 | C18: =apptab2!AD7 -> 80.26244 | D18: =apptab2!AE9 -> 34.34843 | F18: =apptab2!AF5 -> -7.42186 | G18: =apptab2!AG7 -> 33.67398 | H18: =apptab2!AH9 -> -7.68041 | J18: =apptab2!AI5 -> 0.01693 | K18: =apptab2!AJ7 -> 127.89002 | L18: =apptab2!AK9 -> 79.46286
A19: (adjusted) | B19: =apptab2!AC6 -> 5.37371 | C19: =apptab2!AD8 -> 39.68213 | D19: =apptab2!AE10 -> 62.79693 | F19: =apptab2!AF6 -> 6.11528 | G19: =apptab2!AG8 -> 48.47351 | H19: =apptab2!AH10 -> 74.73887 | J19: =apptab2!AI6 -> 4.89561 | K19: =apptab2!AJ8 -> 34.06794 | L19: =apptab2!AK10 -> 54.21988
A22: Notes: Table entries are regression coefficients from univariate regressions of dependent variable shown in row heading on independent variable indicated in column heading. Hours last year includes zeros for non-workers. All models are estimated using data for 691 CZ's and characteristics estimated using 2010-2018 ACS files. "Adjusted" means that the dependent variable or the independent variable (or both) is estimated from a model with CZ dummies and a set of individual characteristics. All regression models are weighted by the (weighted) count of working-age people in the CZ in the ACS files. Robust standard errors in parentheses.

Sheet AT3
B2: Appendix Table 3. Predictions of CZ wage premiums based on public data (top 50 CZs)
B4: Rank | C4: CZ number | D4: Largest city in CZ | E4: Approx. premium | G4: Rank | H4: CZ number | I4: Largest city in CZ | J4: Approx. premium
B5: 1 | C5: =atab3_full!A2 -> 38300 | D5: =SUBSTITUTE(atab3_full!B2," city", "") -> Los Angeles, CA | E5: =atab3_full!C2 -> 0.049924489 | G5: 26 | H5: =atab3_full!A27 -> 16300 | I5: =SUBSTITUTE(atab3_full!B27," city", "") -> Pittsburgh, PA | J5: =atab3_full!C27 -> -0.052859444
B6: 2 | C6: =atab3_full!A3 -> 19400 | D6: =SUBSTITUTE(atab3_full!B3," city", "") -> New York, NY | E6: =atab3_full!C3 -> 0.097572945 | G6: 27 | H6: =atab3_full!A28 -> 33000 | I6: =SUBSTITUTE(atab3_full!B28," city", "") -> Fort Worth, TX | J6: =atab3_full!C28 -> 0.0097144805
B7: 3 | C7: =atab3_full!A4 -> 24300 | D7: =SUBSTITUTE(atab3_full!B4," city", "") -> Chicago, IL | E7: =atab3_full!C4 -> 0.046343025 | G7: 28 | H7: =atab3_full!A29 -> 7400 | I7: =SUBSTITUTE(atab3_full!B29," city", "") -> Orlando, FL | J7: =atab3_full!C29 -> -0.064114183
B8: 4 | C8: =atab3_full!A5 -> 11304 | D8: Washington, DC | E8: =atab3_full!C5 -> 0.1545756 | G8: 29 | H8: =atab3_full!A30 -> 38801 | I8: =SUBSTITUTE(atab3_full!B30," city", "") -> Portland, OR | J8: =atab3_full!C30 -> 0.013963502
B9: 5 | C9: =atab3_full!A6 -> 19600 | D9: =SUBSTITUTE(atab3_full!B6," city", "") -> Newark, NJ | E9: =atab3_full!C6 -> 0.11263122 | G9: 30 | H9: =atab3_full!A31 -> 18000 | I9: =SUBSTITUTE(atab3_full!B31," city", "") -> Buffalo, NY | J9: =atab3_full!C31 -> -0.039841253
B10: 6 | C10: =atab3_full!A7 -> 32000 | D10: =SUBSTITUTE(atab3_full!B7," city", "") -> Houston, TX | E10: =atab3_full!C7 -> 0.045581337 | G10: 31 | H10: =atab3_full!A32 -> 31301 | I10: =SUBSTITUTE(atab3_full!B32," city", "") -> San Antonio, TX | J10: =atab3_full!C32 -> -0.025182236
B11: 7 | C11: =atab3_full!A8 -> 19700 | D11: =SUBSTITUTE(atab3_full!B8," city", "") -> Philadelphia, PA | E11: =atab3_full!C8 -> 0.046094533 | G11: 32 | H11: =atab3_full!A33 -> 37901 | I11: =SUBSTITUTE(atab3_full!B33," city", "") -> Las Vegas, NV | J11: =atab3_full!C33 -> 0.016740318
B12: 8 | C12: =atab3_full!A9 -> 20500 | D12: =SUBSTITUTE(atab3_full!B9," city", "") -> Boston, MA | E12: =atab3_full!C9 -> 0.093689874 | G12: 33 | H12: =atab3_full!A34 -> 31201 | I12: =SUBSTITUTE(atab3_full!B34," city", "") -> Austin, TX | J12: =atab3_full!C34 -> 0.021978047
B13: 9 | C13: =atab3_full!A10 -> 37800 | D13: =SUBSTITUTE(atab3_full!B10," city", "") -> San Francisco, CA | E13: =atab3_full!C10 -> 0.16907614 | G13: 34 | H13: =atab3_full!A35 -> 12701 | I13: =SUBSTITUTE(atab3_full!B35," city", "") -> Cincinnati, OH | J13: =atab3_full!C35 -> -0.019647349
B14: 10 | C14: =atab3_full!A11 -> 9100 | D14: =SUBSTITUTE(atab3_full!B11," city", "") -> Atlanta, GA | E14: =atab3_full!C11 -> 0.00615656 | G14: 35 | H14: =atab3_full!A36 -> 29502 | I14: =SUBSTITUTE(atab3_full!B36," city", "") -> Kansas City, MO | J14: =atab3_full!C36 -> -0.02054416
B15: 11 | C15: =atab3_full!A12 -> 11600 | D15: =SUBSTITUTE(atab3_full!B12," city", "") -> Detroit, MI | E15: =atab3_full!C12 -> -0.031676877 | G15: 36 | H15: =atab3_full!A37 -> 1701 | I15: =SUBSTITUTE(atab3_full!B37," city", "") -> Raleigh, NC | J15: =atab3_full!C37 -> -0.01068214
B16: 12 | C16: =atab3_full!A13 -> 39400 | D16: =SUBSTITUTE(atab3_full!B13," city", "") -> Seattle, WA | E16: =atab3_full!C13 -> 0.073951483 | G16: 37 | H16: =atab3_full!A38 -> 15900 | I16: =SUBSTITUTE(atab3_full!B38," city", "") -> Columbus, OH | J16: =atab3_full!C38 -> -0.023362566
B17: 13 | C17: =atab3_full!A14 -> 33100 | D17: =SUBSTITUTE(atab3_full!B14," city", "") -> Dallas, TX | E17: =atab3_full!C14 -> 0.039217543 | G17: 38 | H17: =atab3_full!A39 -> 900 | I17: =SUBSTITUTE(atab3_full!B39," city", "") -> Charlotte, NC | J17: =atab3_full!C39 -> -0.010709111
B18: 14 | C18: =atab3_full!A15 -> 7000 | D18: =SUBSTITUTE(atab3_full!B15," city", "") -> Miami, FL | E18: =atab3_full!C15 -> -0.035431925 | G18: 39 | H18: =atab3_full!A40 -> 14200 | I18: =SUBSTITUTE(atab3_full!B40," city", "") -> Indianapolis (remaind, IN | J18: =atab3_full!C40 -> -0.02764957
B19: 15 | C19: =atab3_full!A16 -> 35001 | D19: =SUBSTITUTE(atab3_full!B16," city", "") -> Phoenix, AZ | E19: =atab3_full!C16 -> 0.0025758559 | G19: 40 | H19: =atab3_full!A41 -> 36100 | I19: =SUBSTITUTE(atab3_full!B41," city", "") -> Salt Lake City, UT | J19: =atab3_full!C41 -> -0.023369301
B20: 16 | C20: =atab3_full!A17 -> 21501 | D20: =SUBSTITUTE(atab3_full!B17," city", "") -> Minneapolis, MN | E20: =atab3_full!C17 -> 0.036322948 | G20: 41 | H20: =atab3_full!A42 -> 24100 | I20: =SUBSTITUTE(atab3_full!B42," city", "") -> Milwaukee, WI | J20: =atab3_full!C42 -> -0.010708112
... B29: 25 | C29: =atab3_full!A26 -> 24701 | D29: =SUBSTITUTE(atab3_full!B26," city", "") -> St. Louis, MO | E29: =atab3_full!C26 -> -0.024370063 | G29: 50 | H29: =atab3_full!A51 -> 2000 | I29: =SUBSTITUTE(atab3_full!B51," city", "") -> Virginia Beach, VA | J29: =atab3_full!C51 -> -0.020083655
B31: Notes: CZ premiums are best linear predictors of non-disclosed LEHD-based premiums from public ACS data, using as predictors the estimated premium from our first cross-sectional model, the log size of the CZ, and the share of workers in the CZ with some college or more. Premiums are normalized to weighted mean zero across CZs.

Sheet AT4
B6: Appendix Table 4: Comparison of CZ-Level Variance Decompositions for Main Sample, No-Uncertainty Sample, and Non-Mover Sample
D9: Main sample | J9: Non-mover sample | P9: No-uncertainty sample
D10: Person-quarter level | G10: CZ level | J10: Person-quarter level | M10: CZ level | P10: Person-quarter level | S10: CZ level
D11: Std. Dev. or Correlation | E11: Var. Share | G11: Std. Dev. or Correlation | H11: Var. Share | J11: Std. Dev. or Correlation | K11: Var. Share | M11: Std. Dev. or Correlation | N11: Var. Share | P11: Std. Dev. or Correlation | Q11: Var. Share | S11: Std. Dev. or Correlation | T11: Var. Share
D12: (1) | E12: (2) | G12: (1) | H12: (2) | J12: (1) | K12: (2) | M12: (3) | N12: (4) | P12: (1) | Q12: (2) | S12: (5) | T12: (6)
B13: Log earnings or mean log earnings | D13: =VALUE(disc7.2!B7) -> 0.6526 | E13: 1 | G13: =VALUE(disc7.2!C7) -> 0.1467 | H13: 1 | J13: =VALUE(disc7.18!B26) -> 0.6455 | K13: 1 | M13: =VALUE(disc7.18!C26) -> 0.14 | N13: 1 | P13: =VALUE(disc7.19!B7) -> 0.6533 | Q13: 1 | S13: =VALUE(disc7.19!C7) -> 0.1447 | T13: 1
B14: Variance components (std. deviations in odd-number columns, variance shares in even-numbered columns)
B15: Person effects | D15: =SQRT((D$13^2)*E15) -> 0.52387158 | E15: =VALUE(disc7.2!B8) -> 0.6444 | G15: =SQRT((G$13^2)*H15) -> 0.08079162 | H15: =VALUE(disc7.2!C8) -> 0.3033 | J15: =SQRT((J$13^2)*K15) -> 0.52820678 | K15: =VALUE(disc7.18!B27) -> 0.6696 | M15: =SQRT((M$13^2)*N15) -> 0.0756 | N15: =VALUE(disc7.18!C27) -> 0.2916 | P15: =SQRT((P$13^2)*Q15) -> 0.52536857 | Q15: =VALUE(disc7.19!B8) -> 0.6467 | S15: =SQRT((S$13^2)*T15) -> 0.080617511 | T15: =VALUE(disc7.19!C8) -> 0.3104
B16: Firm effects | D16: =SQRT((D$13^2)*E16) -> 0.22284164 | E16: =VALUE(disc7.2!B9) -> 0.1166 | G16: =SQRT((G$13^2)*H16) -> 0.079353717 | H16: =VALUE(disc7.2!C9) -> 0.2926 | J16: =SQRT((J$13^2)*K16) -> 0.22032268 | K16: =VALUE(disc7.18!B28) -> 0.1165 | M16: =SQRT((M$13^2)*N16) -> 0.07724144 | N16: =VALUE(disc7.18!C28) -> 0.3044 | P16: =SQRT((P$13^2)*Q16) -> 0.22706287 | Q16: =VALUE(disc7.19!B9) -> 0.1208 | S16: =SQRT((S$13^2)*T16) -> 0.076963535 | T16: =VALUE(disc7.19!C9) -> 0.2829
B17: Covariate index (Xβ) | D17: =SQRT((D$13^2)*E17) -> 0.13467931 | E17: =VALUE(disc7.2!B10) -> 0.04259 | G17: =SQRT((G$13^2)*H17) -> 0.0057344503 | H17: =VALUE(disc7.2!C10) -> 0.001528 | J17: =SQRT((J$13^2)*K17) -> 0.13418018 | K17: =VALUE(disc7.18!B29) -> 0.04321 | M17: =SQRT((M$13^2)*N17) -> 0.0059281363 | N17: =VALUE(disc7.18!C29) -> 0.001793 | P17: =SQRT((P$13^2)*Q17) -> 0.1344751 | Q17: =VALUE(disc7.19!B10) -> 0.04237 | S17: =SQRT((S$13^2)*T17) -> 0.0060445816 | T17: =VALUE(disc7.19!C10) -> 0.001745
B18: Residual | D18: =SQRT((D$13^2)*E18) -> 0.23210919 | E18: =VALUE(disc7.2!B11) -> 0.1265 | G18: =SQRT((G$13^2)*H18) -> #VALUE! | H18: =VALUE(disc7.2!C11) -> #VALUE! | J18: =SQRT((J$13^2)*K18) -> 0.22360776 | K18: =VALUE(disc7.18!B30) -> 0.12 | M18: =SQRT((M$13^2)*N18) -> #VALUE! | N18: =VALUE(disc7.18!C30) -> #VALUE! | P18: =SQRT((P$13^2)*Q18) -> 0.2353694 | Q18: =VALUE(disc7.19!B11) -> 0.1298 | S18: =SQRT((S$13^2)*T18) -> 0.0001447 | T18: =VALUE(disc7.19!C11) -> 1e-06
B19: Covariance components (correlations in odd-number columns, variance shares in even-numbered columns)
B20: Person & firm | D20: =(E20*(D13^2)/2)/(D15*D16) -> 0.18240761 | E20: =VALUE(disc7.2!B12) -> 0.1 | G20: =(H20*(G13^2)/2)/(G15*G16) -> 0.64182189 | H20: =VALUE(disc7.2!C12) -> 0.3824 | J20: =(K20*(J13^2)/2)/(J15*J16) -> 0.15862881 | K20: =VALUE(disc7.18!B31) -> 0.08861 | M20: =(N20*(M13^2)/2)/(M15*M16) -> 0.61742429 | N20: =VALUE(disc7.18!C31) -> 0.3679 | P20: =(Q20*(P13^2)/2)/(P15*P16) -> 0.16525822 | Q20: =VALUE(disc7.19!B12) -> 0.09238 | S20: =(T20*(S13^2)/2)/(S15*S16) -> 0.64336803 | T20: =VALUE(disc7.19!C12) -> 0.3813
B21: Person & covariate index | D21: =(E21*(D13^2)/2)/(D15*D17) -> -0.099900213 | E21: =VALUE(disc7.2!B13) -> -0.0331 | G21: =(H21*(G13^2)/2)/(G15*G17) -> 0.22759037 | H21: =VALUE(disc7.2!C13) -> 0.009799 | J21: =(K21*(J13^2)/2)/(J15*J17) -> -0.11449265 | K21: =VALUE(disc7.18!B32) -> -0.03895 | M21: =(N21*(M13^2)/2)/(M15*M17) -> 0.33674939 | N21: =VALUE(disc7.18!C32) -> 0.0154 | P21: =(Q21*(P13^2)/2)/(P15*P17) -> -0.10275989 | Q21: =VALUE(disc7.19!B13) -> -0.03402 | S21: =(T21*(S13^2)/2)/(S15*S17) -> 0.25887999 | T21: =VALUE(disc7.19!C13) -> 0.01205
B22: Firm & covariate index | D22: =(E22*(D13^2)/2)/(D16*D17) -> 0.020469759 | E22: =VALUE(disc7.2!B15) -> 0.002885 | G22: =(H22*(G13^2)/2)/(G16*G17) -> 0.24521663 | H22: =VALUE(disc7.2!C15) -> 0.01037 | J22: =(K22*(J13^2)/2)/(J16*J17) -> 0.012219797 | K22: =VALUE(disc7.18!B34) -> 0.001734 | M22: =(N22*(M13^2)/2)/(M16*M17) -> 0.40642695 | N22: =VALUE(disc7.18!C34) -> 0.01899 | P22: =(Q22*(P13^2)/2)/(P16*P17) -> 0.01976454 | Q22: =VALUE(disc7.19!B15) -> 0.002828 | S22: =(T22*(S13^2)/2)/(S16*S17) -> 0.23899033 | T22: =VALUE(disc7.19!C15) -> 0.01062
B23: Sample size (billions of person-quarter observations) | G23: =VALUE(disc7.2!$B$18)/1000000000 -> 2.523 | M23: =VALUE(disc7.18!$B$37)/1000000000 -> 1.835 | S23: =VALUE(disc7.19!$B$18)/1000000000 -> 1.901
B25: Notes: Table shows variance decompositions of CZ-level mean earnings based on equation (6). Entries in odd-numbered columns "variance components" are standard deviations of the earnings components indicated in row headings; for "covariance components" they are the estimated correlations of the indicated components. Entries in even-numbered columns are variance shares explained by the variance or covariance components.

Sheet AT5
B6: Appendix Table 5: Summary of AKM model estimates by education group
D9: Low education sample | J9: High education sample
D10: Person-quarter level | G10: CZ level | J10: Person-quarter level | M10: CZ level
D11: Std. Dev. or Correlation | E11: Var. Share | G11: Std. Dev. or Correlation | H11: Var. Share | J11: Std. Dev. or Correlation | K11: Var. Share | M11: Std. Dev. or Correlation | N11: Var. Share
D12: (1) | E12: (2) | G12: (3) | H12: (4) | J12: (5) | K12: (6) | M12: (7) | N12: (8)
B13: Log earnings or mean log earnings | D13: =VALUE(disc7.17!B6) -> 0.5137 | E13: 1 | G13: =VALUE(disc7.17!C6) -> 0.0973 | H13: 1 | J13: =VALUE(disc7.17!D6) -> 0.6784 | K13: 1 | M13: =VALUE(disc7.17!E6) -> 0.1783 | N13: 1
B14: Variance components (std. deviations in odd-number columns, variance shares in even-numbered columns)
B15: Person effects | D15: =SQRT((D$13^2)*E15) -> 0.40925483 | E15: =VALUE(disc7.17!B7) -> 0.6347 | G15: =SQRT((G$13^2)*H15) -> 0.055307155 | H15: =VALUE(disc7.17!C7) -> 0.3231 | J15: =SQRT((J$13^2)*K15) -> 0.55859968 | K15: =VALUE(disc7.17!D7) -> 0.678 | M15: =SQRT((M$13^2)*N15) -> 0.1011607 | N15: =VALUE(disc7.17!E7) -> 0.3219
B16: Firm effects | D16: =SQRT((D$13^2)*E16) -> 0.21161697 | E16: =VALUE(disc7.17!B8) -> 0.1697 | G16: =SQRT((G$13^2)*H16) -> 0.059057173 | H16: =VALUE(disc7.17!C8) -> 0.3684 | J16: =SQRT((J$13^2)*K16) -> 0.22273846 | K16: =VALUE(disc7.17!D8) -> 0.1078 | M16: =SQRT((M$13^2)*N16) -> 0.087494264 | N16: =VALUE(disc7.17!E8) -> 0.2408
B17: Covariate index (Xβ) | D17: =SQRT((D$13^2)*E17) -> 0.12708236 | E17: =VALUE(disc7.17!B9) -> 0.0612 | G17: =SQRT((G$13^2)*H17) -> 0.0072994457 | H17: =VALUE(disc7.17!C9) -> 0.005628 | J17: =SQRT((J$13^2)*K17) -> 0.12994504 | K17: =VALUE(disc7.17!D9) -> 0.03669 | M17: =SQRT((M$13^2)*N17) -> 0.0052500192 | N17: =VALUE(disc7.17!E9) -> 0.000867
B18: Residual | D18: =SQRT((D$13^2)*E18) -> 0.19214028 | E18: =VALUE(disc7.17!B10) -> 0.1399 | G18: =SQRT((G$13^2)*H18) -> 0.00054174347 | H18: =VALUE(disc7.17!C10) -> 3.1e-05 | J18: =SQRT((J$13^2)*K18) -> 0.2443182 | K18: =VALUE(disc7.17!D10) -> 0.1297 | M18: =SQRT((M$13^2)*N18) -> 0.00043674402 | N18: =VALUE(disc7.17!E10) -> 6e-06
B19: Covariance components (correlations in odd-number columns, variance shares in even-numbered columns)
B20: Person & firm | D20: =(E20*(D13^2)/2)/(D15*D16) -> 0.1117341 | E20: =VALUE(disc7.17!B11) -> 0.07334 | G20: =(H20*(G13^2)/2)/(G15*G16) -> 0.43274446 | H20: =VALUE(disc7.17!C11) -> 0.2986 | J20: =(K20*(J13^2)/2)/(J15*J16) -> 0.16654419 | K20: =VALUE(disc7.17!D11) -> 0.09005 | M20: =(N20*(M13^2)/2)/(M15*M16) -> 0.75301935 | N20: =VALUE(disc7.17!E11) -> 0.4193
B21: Person & covariate index | D21: =(E21*(D13^2)/2)/(D15*D17) -> -0.1766217 | E21: =VALUE(disc7.17!B12) -> -0.06962 | G21: =(H21*(G13^2)/2)/(G15*G17) -> -0.24705237 | H21: =VALUE(disc7.17!C12) -> -0.02107 | J21: =(K21*(J13^2)/2)/(J15*J17) -> -0.13913836 | K21: =VALUE(disc7.17!D12) -> -0.04389 | M21: =(N21*(M13^2)/2)/(M15*M17) -> 0.31755236 | N21: =VALUE(disc7.17!E12) -> 0.01061
B22: Firm & covariate index | D22: =(E22*(D13^2)/2)/(D16*D17) -> -0.017397711 | E22: =VALUE(disc7.17!B14) -> -0.003546 | G22: =(H22*(G13^2)/2)/(G16*G17) -> 0.22598443 | H22: =VALUE(disc7.17!C14) -> 0.02058 | J22: =(K22*(J13^2)/2)/(J16*J17) -> 0.015439598 | K22: =VALUE(disc7.17!D14) -> 0.001942 | M22: =(N22*(M13^2)/2)/(M16*M17) -> 0.2554502 | N22: =VALUE(disc7.17!E14) -> 0.007382
B24: Notes: Table shows variance decompositions based on equation (4). Columns 1-2 and 5-6 pertain to the variance of individual quarterly earnings. Columns 3-4 and 7-8 pertain to the variance of mean earnings by CZ. Entries in odd-numbered columns for "variance components" are standard deviations of the earnings components indicated in row headings; for "covariance components" they are the estimated correlations of the indicated components. Entries in even-numbered columns are variance shares explained by the variance or covariance components.

Sheet AT6
B6: Appendix Table 6: Variance Decomposition of CZ Wage Gap between High- and Low-education Workers
D8: Variance Decomposition of Wage Gap
D9: Std. Dev. or Correlation | E9: Var. Share
D10: (1) | E10: (2)
B11: Wage gap (high- versus low-education workers) | D11: =VALUE(disc7.15!B5) -> 0.1067 | E11: 1
B12: Components of Wage Gap (column 1 = std. dev.)
B13: Difference in mean person effects | D13: =SQRT((D$11^2)*E13) -> 0.074315612 | E13: =VALUE(disc7.15!B7) -> 0.4851
B14: Difference in covariate indexes | D14: =SQRT((D$11^2)*E14) -> 0.0058403023 | E14: =VALUE(disc7.15!B10) -> 0.002996
B15: Difference in mean CZ wage effect: | D15: =SQRT((D$11^2)*E15) -> 0.038333525 | E15: =VALUE(disc7.15!N6) -> 0.129071
C16: Of which:
C17: Relative wage premium | D17: =SQRT((D$11^2)*E17) -> 0.013883306 | E17: =VALUE(disc7.15!B6) -> 0.01693
C18: Composition | D18: =SQRT((D$11^2)*E18) -> 0.027515363 | E18: =VALUE(disc7.15!B8) -> 0.0665
C19: Interaction | D19: =SQRT((D$11^2)*E19) -> 0.0020854323 | E19: =VALUE(disc7.15!B9) -> 0.000382
B21: Covariance Terms (column 1 = correlation of terms)
B22: Cov(Person effects, cov. index) | D22: =E22/(2*SQRT(E13*E14)) -> -0.25129218 | E22: =VALUE(disc7.15!B17) -> -0.01916
B23: Cov(Person effects, CZ effect) | D23: =E23/(2*SQRT(E13*E15)) -> 0.83069576 | E23: =E25+E26+E27 -> 0.415721
C24: Of which:
C25: Cov(Person effects, relative wage premium) | D25: =E25/(2*SQRT(E13*E17)) -> 0.78455878 | E25: =VALUE(disc7.15!B11) -> 0.1422
C26: Cov(Person effects, composition) | D26: =E26/(2*SQRT(E13*E18)) -> 0.78504157 | E26: =VALUE(disc7.15!B15) -> 0.282
C27: Cov(Person effects, interaction) | D27: =E27/(2*SQRT(E13*E19)) -> -0.31143493 | E27: =VALUE(disc7.15!B16) -> -0.008479
B28: Sum of all other covariance terms | D28: -- | E28: =VALUE(disc7.15!B12)+VALUE(disc7.15!B13)+VALUE(disc7.15!B14)+VALUE(disc7.15!B18)+VALUE(disc7.15!B19)+VALUE(disc7.15!B20) -> 0.03158
B30: Notes: Table shows variance decomposition of the difference in mean log earnings of college and non-college workers in a CZ, using equations (12) and (13). Analysis is weighted by CZ size.

Sheet AT7
C2: Appendix Table 7: Elasticities of Housing Values and Rents with respect to CZ Size
E4: All CZ's | G4: Largest 50 CZ's
E5: (1) | G5: (2)
C7: Housing Prices (log of home value for owners)
C8: Unadjusted | E8: =apptab7!B5 -> 0.2536 | G8: =apptab7!C5 -> 0.36711
E9: =apptab7!B6 -> 0.02358 | G9: =apptab7!C6 -> 0.04988
C10: Quality Adjusted | E10: =apptab7!D5 -> 0.22667 | G10: =apptab7!E5 -> 0.414
E11: =apptab7!D6 -> 0.03148 | G11: =apptab7!E6 -> 0.05945
C13: Monthly Rent (log of rent for renters)
C14: Unadjusted | E14: =apptab7!F5 -> 0.17028 | G14: =apptab7!G5 -> 0.18622
E15: =apptab7!F6 -> 0.0082 | G15: =apptab7!G6 -> 0.02178
C16: Quality Adjusted | E16: =apptab7!H5 -> 0.17812 | G16: =apptab7!I5 -> 0.22259
E17: =apptab7!H6 -> 0.00969 | G17: =apptab7!I6 -> 0.02368
C19: Note: Table entries are regression coefficients (and standard errors) from weighted OLS regressions of CZ-average housing price measure in row heading on constant and log of number of workers in CZ. Regressions are weighted by number of workers in CZ. Sample in column 1 is set of 678 CZ's in 2018 5-year ACS with non-missing data. Sample in column 2 is 50 largest CZ's, ranked by number of workers. Quality adjusted values and rents derive from regressions on indicator for type of housing unit, number of bedrooms, log of total number of rooms, year of construction, and indicator for mortgage (for home values) or set of indicators for inclusion of utility costs (for rents).

Sheet disc7.1
A1: Output 1: Descriptive Table
B3: (1) | C3: (2) | D3: (3) | E3: (4) | F3: (5)
C4: Sample 8 | E4: Sample 9 | F4: Sample 10
B5: Sample 8 | C5: CZ stayers subgroup | D5: CZ movers subgroup | E5: Event study sample - firm | F5: Event study sample - CZ
B6: mean/sd | C6: mean/sd | D6: mean/sd | E6: mean/sd | F6: mean/sd
A7: lne | B7: 9.434 | C7: 9.431 | D7: 9.441 | E7: 9.506 | F7: 9.548
B8: (.5956) | C8: (.5945) | D8: (.5985) | E8: (.6334) | F8: (.6501)
A9: age | B9: 42.44 | C9: 43.56 | D9: 39.45 | E9: 40.93 | F9: 40.08
B10: (10.78) | C10: (10.73) | D10: (10.32) | E10: (10.63) | F10: (10.56)
A11: gender | B11: .4728 | C11: .49 | D11: .4269 | E11: .4605 | F11: .4253
B12: (.4993) | C12: (.4999) | D12: (.4946) | E12: (.4984) | F12: (.4944)
A13: forborn | B13: .1612 | C13: .1676 | D13: .1439 | E13: .1512 | F13: .1346
B14: (.3677) | C14: -.3735 | D14: (.351) | E14: (.3582) | F14: (.3413)
A15: hisp | B15: .1333 | C15: .138 | D15: .1206 | E15: .1214 | F15: .1029
B16: (.3399) | C16: (.3449) | D16: (.3256) | E16: (.3266) | F16: (.3039)
A17: czcnt1 | B17: .7276 | E17: .6677
B18: (.4452) | E18: (.471)
A19: czcnt2 | B19: .2033 | D19: .7462 | E19: .3323
B20: (.4024) | D20: (.4352) | E20: (.471)
A21: czcnt3 | B21: .06913 | D21: .2538
B22: (.2537) | D22: (.4352)
A23: naics4dswitch0 | B23: .6483 | C23: .6777 | D23: .5697 | E23: .6238 | F23: .9949
B24: (.4775) | C24: (.4673) | D24: (.4951) | E24: (.4844) | F24: (.07126)
A25: naics4dswitch1 | B25: .2466 | C25: .2281 | D25: .296 | E25: .3666 | F25: .005103
B26: (.4311) | C26: (.4196) | D26: (.4565) | E26: (.4819) | F26: (.07125)
A27: naics4dswitch2 | B27: .1051 | C27: .09412 | D27: .1343 | E27: .009586
B28: (.3066) | C28: (.292) | D28: (.341) | E28: (.09744)
A29: qobserved | B29: 25.88 | C29: 26.84 | D29: 23.32
B30: (7.658) | C30: (7.677) | D30: (6.988)
A31: Observations | B31: 2523000000 | C31: 1835000000 | D31: 687200000 | E31: 193400000 | F31: 67170000
A32: Unique PIKs | B32: 112100000 | C32: 78590000 | D32: 33520000 | E32: 19340000 | F32: 6717000

Sheet disc7.2
A1: Output 2: Main decomposition AKM
B3: Sample 8
B4: Person-quarter | C4: CZ
B6: SD & Var% | C6: SD & Var%
A7: y (sd) | B7: .6526 | C7: .1467
A8: pe - variance share | B8: .6444 | C8: .3033
A9: fe - variance share | B9: .1166 | C9: .2926 | F9: .049658396216 | G9: .2228416393226365
A10: xb - variance share | B10: .04259 | C10: .001528
A11: r - variance share | B11: .1265
A12: cov(pe,fe) - variance share | B12: .1 | C12: .3824
A13: cov(pe,xb) - variance share | B13: -.0331 | C13: .009799
A14: cov(pe,r) - variance share | B14: 0
A15: cov(fe,xb) - variance share | B15: .002885 | C15: .01037
A16: cov(fe,r) - variance share | B16: 0
A17: cov(xb,r) - variance share | B17: .000186
A18: Number of Person-quarter observations | B18: 2523000000
A23: sum of variance shares | B23: .9300900000000001
A24: sum of covariance shares | B24: .069971
A26: cov(pe,fe)/var(fe) | B26: .4288164665523156
A28: correl (pe,fe) | B28: .1824076142937905

Sheet disc7.3
A1: Regression coefficients on experience regressors in alternative AKM model specifications
B4: Sample 8
B6: young subgroup
B7: (1) | C7: (2)
A8: coefficients on: | B8: top10 spec | C8: top 25 spec
A10: timeinGall | B10: .004267 | C10: .003482
B11: (.0003357) | C11: (.0003689)
A13: timeintop10 | B13: .004061
B14: (.001727)
A16: 1.intop10 # c.timeinGall | B16: .00179
B17: (.001655)
A19: 1.intop10 # c.timeintop10 | B19: -.001961
B20: (.0003007)
A22: timeintop25 | C22: .003954
C23: (.0009851)
A25: 1.intop25 # c.timeinGall | C25: .0004641
C26: (.0009549)
A28: 1.intop25 # c.timeintop25 | C28: -.000383
C29: (.0002544)
A32: Number of Person-quarter observations | B32: 478600000 | C32: 478600000

Sheet disc7.4
A1: Models for $ \Psi_{jc} $
B2: Sample 8
B3: 1 | C3: 2 | D3: 3 | E3: 4 | F3: 5
B4: CZ effects | C4: Industry effects | D4: CZ + industry effects | E4: CZ+ind effects + sjc | F4: CZ+ind effects + ln(njc)
A6: sjc | E6: 0.451***
E7: (0.0325)
A9: ln(njc) | F9: 0.0440***
F10: (0.00244)
A12: Number of CZ-industries | B12: 17000 | C12: 17000 | D12: 17000 | E12: 17000 | F12: 17000
A13: Number of Person-quarter observations | B13: 2523000000 | C13: 2523000000 | D13: 2523000000 | E13: 2523000000 | F13: 2523000000
A14: R-squared | B14: 0.326 | C14: 0.570 | D14: 0.873 | E14: 0.885 | F14: 0.892
A15: RMSE | B15: 0.117 | C15: 0.0912 | D15: 0.0506 | E15: 0.0483 | F15: 0.0467

Sheet disc7.5
A1: Variance decompositions of fe_c
B2: Sample 8
B3: (2-digit industries) | C3: (4-digit industries)
B4: SD & Var% | C4: SD & Var%
A5: SD(dependent variable) | B5: .07934 | C5: .07934
A6: var(A) share
A7: var(B) share | B7: .9424 | C7: .913
A8: var(C) share | B8: .02522 | C8: .02578
A9: var(D) share | B9: .02197 | C9: .04399
A10: cov(A,B) share
A11: cov(A,C) share
A12: cov(A,D) share
A13: cov(B,C) share | B13: .01521 | C13: .06354
A14: cov(B,D) share | B14: -.005893 | C14: -.05435
A15: cov(C,D) share | B15: .001096 | C15: .008037
A16: Number of Person-quarter observations | B16: 2523000000

Sheet disc7.6
A1: Regressions y pe fe sdpe pedec1 pedec10 on earnings & size & education (CZ level)
B4: y | C4: pe | D4: fe | E4: sdpe | F4: pedec1 | G4: pedec10 | H4: phi_c_B | I4: phi_c_C | J4: phi_c_D | K4: corr_pe_fe
A6: y_c | C6: 0.499 | D6: 0.489 | E6: 0.240 | F6: -0.0871 | G6: 0.213 | H6: 0.475 | I6: 0.0181 | J6: -0.00445 | K6: 0.451
C7: (0.0205) | D7: (0.0187) | E7: (0.0219) | F7: (0.0124) | G7: (0.00948) | H7: (0.0188) | I7: (0.00641) | J7: (0.00840) | K7: (0.0251)
A10: lnN_c | B10: 0.0753 | C10: 0.0397 | D10: 0.0340 | E10: 0.0250 | F10: -0.00480 | G10: 0.0185 | H10: 0.0370 | I10: 0.0000369 | J10: -0.00313 | K10: 0.0394
B11: (0.00808) | C11: (0.00655) | D11: (0.00310) | E11: (0.00202) | F11: (0.00253) | G11: (0.00221) | H11: (0.00262) | I11: (0.000402) | J11: (0.000832) | K11: (0.00354)
A13: educ_c | B13: 1.683 | C13: 0.982 | D13: 0.664 | E13: 0.466 | F13: -0.202 | G13: 0.414 | H13: 0.733 | I13: -0.00953 | J13: -0.0594 | K13: 0.850
